[Thu May 27 18:45:43.968379 2021] [mpm_prefork:notice] [pid 487891] AH00163: Apache/2.4.41 (Ubuntu) OpenSSL/1.1.1f mod_wsgi/4.6.8 Python/3.8 configured -- resuming normal operations
[Thu May 27 18:45:43.968482 2021] [core:notice] [pid 487891] AH00094: Command line: '/usr/sbin/apache2'
Exception ignored in: <generator object path at 0x7fd04f9686d0>
Traceback (most recent call last):
  File "/usr/lib/python3.8/importlib/resources.py", line 190, in path
NameError: name 'FileNotFoundError' is not defined
Exception ignored in: <generator object path at 0x7fd04f9686d0>
Traceback (most recent call last):
  File "/usr/lib/python3.8/importlib/resources.py", line 190, in path
NameError: name 'FileNotFoundError' is not defined
Exception ignored in: <generator object path at 0x7fd04f9686d0>
Traceback (most recent call last):
  File "/usr/lib/python3.8/importlib/resources.py", line 190, in path
NameError: name 'FileNotFoundError' is not defined
Exception ignored in: <generator object path at 0x7fd04f9686d0>
Traceback (most recent call last):
  File "/usr/lib/python3.8/importlib/resources.py", line 190, in path
NameError: name 'FileNotFoundError' is not defined
Exception ignored in: <generator object path at 0x7fd04f9686d0>
Traceback (most recent call last):
  File "/usr/lib/python3.8/importlib/resources.py", line 190, in path
NameError: name 'FileNotFoundError' is not defined
Exception ignored in: <generator object path at 0x7fd04f9686d0>
Traceback (most recent call last):
  File "/usr/lib/python3.8/importlib/resources.py", line 190, in path
NameError: name 'FileNotFoundError' is not defined
Exception ignored in: <generator object path at 0x7fd04f9686d0>
Traceback (most recent call last):
  File "/usr/lib/python3.8/importlib/resources.py", line 190, in path
NameError: name 'FileNotFoundError' is not defined
Exception ignored in: <generator object path at 0x7fd04f9686d0>
Traceback (most recent call last):
  File "/usr/lib/python3.8/importlib/resources.py", line 190, in path
NameError: name 'FileNotFoundError' is not defined
Exception ignored in: <generator object path at 0x7fd04f9686d0>
Traceback (most recent call last):
  File "/usr/lib/python3.8/importlib/resources.py", line 190, in path
NameError: name 'FileNotFoundError' is not defined
Exception ignored in: <generator object path at 0x7fd04f9686d0>
Traceback (most recent call last):
  File "/usr/lib/python3.8/importlib/resources.py", line 190, in path
NameError: name 'FileNotFoundError' is not defined
Exception ignored in: <generator object path at 0x7fd04f9686d0>
Traceback (most recent call last):
  File "/usr/lib/python3.8/importlib/resources.py", line 190, in path
NameError: name 'FileNotFoundError' is not defined
Exception ignored in: <generator object path at 0x7fd04f9686d0>
Traceback (most recent call last):
  File "/usr/lib/python3.8/importlib/resources.py", line 190, in path
NameError: name 'FileNotFoundError' is not defined
[Thu May 27 20:44:45.345855 2021] [mpm_prefork:notice] [pid 487891] AH00169: caught SIGTERM, shutting down
[Thu May 27 20:44:45.512104 2021] [mpm_prefork:notice] [pid 488869] AH00163: Apache/2.4.41 (Ubuntu) OpenSSL/1.1.1f mod_wsgi/4.6.8 Python/3.8 configured -- resuming normal operations
[Thu May 27 20:44:45.512182 2021] [core:notice] [pid 488869] AH00094: Command line: '/usr/sbin/apache2'
[Thu May 27 20:44:58.607780 2021] [wsgi:error] [pid 488873] [client 106.220.93.219:58693] mod_wsgi (pid=488873): Failed to exec Python script file '/var/www/gridsai/gridsai.wsgi'.
[Thu May 27 20:44:58.607906 2021] [wsgi:error] [pid 488873] [client 106.220.93.219:58693] mod_wsgi (pid=488873): Exception occurred processing WSGI script '/var/www/gridsai/gridsai.wsgi'.
[Thu May 27 20:44:58.615225 2021] [wsgi:error] [pid 488873] [client 106.220.93.219:58693] Traceback (most recent call last):
[Thu May 27 20:44:58.615317 2021] [wsgi:error] [pid 488873] [client 106.220.93.219:58693]   File "/var/www/gridsai/gridsai.wsgi", line 9, in <module>
[Thu May 27 20:44:58.615327 2021] [wsgi:error] [pid 488873] [client 106.220.93.219:58693]     from gridsai import app as application
[Thu May 27 20:44:58.615338 2021] [wsgi:error] [pid 488873] [client 106.220.93.219:58693]   File "/var/www/gridsai/gridsai/__init__.py", line 7, in <module>
[Thu May 27 20:44:58.618979 2021] [wsgi:error] [pid 488873] [client 106.220.93.219:58693]   File "<frozen importlib._bootstrap>", line 991, in _find_and_load
[Thu May 27 20:44:58.619010 2021] [wsgi:error] [pid 488873] [client 106.220.93.219:58693]   File "<frozen importlib._bootstrap>", line 975, in _find_and_load_unlocked
[Thu May 27 20:44:58.619020 2021] [wsgi:error] [pid 488873] [client 106.220.93.219:58693]   File "<frozen importlib._bootstrap>", line 671, in _load_unlocked
[Thu May 27 20:44:58.619030 2021] [wsgi:error] [pid 488873] [client 106.220.93.219:58693]   File "<frozen importlib._bootstrap_external>", line 779, in exec_module
[Thu May 27 20:44:58.619039 2021] [wsgi:error] [pid 488873] [client 106.220.93.219:58693]   File "<frozen importlib._bootstrap_external>", line 915, in get_code
[Thu May 27 20:44:58.619049 2021] [wsgi:error] [pid 488873] [client 106.220.93.219:58693]   File "<frozen importlib._bootstrap_external>", line 972, in get_data
[Thu May 27 20:44:58.619103 2021] [wsgi:error] [pid 488873] [client 106.220.93.219:58693] PermissionError: [Errno 13] Permission denied: '/var/www/gridsai/gridsai/shuffleprocess.py'
[Thu May 27 20:45:00.047323 2021] [wsgi:error] [pid 488871] [client 106.220.93.219:58690] mod_wsgi (pid=488871): Failed to exec Python script file '/var/www/gridsai/gridsai.wsgi'., referer: https://grids-ai.com/
[Thu May 27 20:45:00.047441 2021] [wsgi:error] [pid 488871] [client 106.220.93.219:58690] mod_wsgi (pid=488871): Exception occurred processing WSGI script '/var/www/gridsai/gridsai.wsgi'., referer: https://grids-ai.com/
[Thu May 27 20:45:00.050089 2021] [wsgi:error] [pid 488871] [client 106.220.93.219:58690] Traceback (most recent call last):, referer: https://grids-ai.com/
[Thu May 27 20:45:00.050207 2021] [wsgi:error] [pid 488871] [client 106.220.93.219:58690]   File "/var/www/gridsai/gridsai.wsgi", line 9, in <module>, referer: https://grids-ai.com/
[Thu May 27 20:45:00.050217 2021] [wsgi:error] [pid 488871] [client 106.220.93.219:58690]     from gridsai import app as application, referer: https://grids-ai.com/
[Thu May 27 20:45:00.050239 2021] [wsgi:error] [pid 488871] [client 106.220.93.219:58690]   File "/var/www/gridsai/gridsai/__init__.py", line 7, in <module>, referer: https://grids-ai.com/
[Thu May 27 20:45:00.050250 2021] [wsgi:error] [pid 488871] [client 106.220.93.219:58690]   File "<frozen importlib._bootstrap>", line 991, in _find_and_load, referer: https://grids-ai.com/
[Thu May 27 20:45:00.050260 2021] [wsgi:error] [pid 488871] [client 106.220.93.219:58690]   File "<frozen importlib._bootstrap>", line 975, in _find_and_load_unlocked, referer: https://grids-ai.com/
[Thu May 27 20:45:00.050270 2021] [wsgi:error] [pid 488871] [client 106.220.93.219:58690]   File "<frozen importlib._bootstrap>", line 671, in _load_unlocked, referer: https://grids-ai.com/
[Thu May 27 20:45:00.050280 2021] [wsgi:error] [pid 488871] [client 106.220.93.219:58690]   File "<frozen importlib._bootstrap_external>", line 779, in exec_module, referer: https://grids-ai.com/
[Thu May 27 20:45:00.050290 2021] [wsgi:error] [pid 488871] [client 106.220.93.219:58690]   File "<frozen importlib._bootstrap_external>", line 915, in get_code, referer: https://grids-ai.com/
[Thu May 27 20:45:00.050301 2021] [wsgi:error] [pid 488871] [client 106.220.93.219:58690]   File "<frozen importlib._bootstrap_external>", line 972, in get_data, referer: https://grids-ai.com/
[Thu May 27 20:45:00.050330 2021] [wsgi:error] [pid 488871] [client 106.220.93.219:58690] PermissionError: [Errno 13] Permission denied: '/var/www/gridsai/gridsai/shuffleprocess.py', referer: https://grids-ai.com/
[Thu May 27 20:48:55.770349 2021] [wsgi:error] [pid 488870] [client 106.220.93.219:58729] mod_wsgi (pid=488870): Failed to exec Python script file '/var/www/gridsai/gridsai.wsgi'.
[Thu May 27 20:48:55.770458 2021] [wsgi:error] [pid 488870] [client 106.220.93.219:58729] mod_wsgi (pid=488870): Exception occurred processing WSGI script '/var/www/gridsai/gridsai.wsgi'.
[Thu May 27 20:48:55.772132 2021] [wsgi:error] [pid 488870] [client 106.220.93.219:58729] Traceback (most recent call last):
[Thu May 27 20:48:55.772191 2021] [wsgi:error] [pid 488870] [client 106.220.93.219:58729]   File "/var/www/gridsai/gridsai.wsgi", line 9, in <module>
[Thu May 27 20:48:55.772196 2021] [wsgi:error] [pid 488870] [client 106.220.93.219:58729]     from gridsai import app as application
[Thu May 27 20:48:55.772203 2021] [wsgi:error] [pid 488870] [client 106.220.93.219:58729]   File "/var/www/gridsai/gridsai/__init__.py", line 7, in <module>
[Thu May 27 20:48:55.772209 2021] [wsgi:error] [pid 488870] [client 106.220.93.219:58729]   File "<frozen importlib._bootstrap>", line 991, in _find_and_load
[Thu May 27 20:48:55.772215 2021] [wsgi:error] [pid 488870] [client 106.220.93.219:58729]   File "<frozen importlib._bootstrap>", line 975, in _find_and_load_unlocked
[Thu May 27 20:48:55.772222 2021] [wsgi:error] [pid 488870] [client 106.220.93.219:58729]   File "<frozen importlib._bootstrap>", line 671, in _load_unlocked
[Thu May 27 20:48:55.772228 2021] [wsgi:error] [pid 488870] [client 106.220.93.219:58729]   File "<frozen importlib._bootstrap_external>", line 779, in exec_module
[Thu May 27 20:48:55.772234 2021] [wsgi:error] [pid 488870] [client 106.220.93.219:58729]   File "<frozen importlib._bootstrap_external>", line 915, in get_code
[Thu May 27 20:48:55.772240 2021] [wsgi:error] [pid 488870] [client 106.220.93.219:58729]   File "<frozen importlib._bootstrap_external>", line 972, in get_data
[Thu May 27 20:48:55.772257 2021] [wsgi:error] [pid 488870] [client 106.220.93.219:58729] PermissionError: [Errno 13] Permission denied: '/var/www/gridsai/gridsai/shuffleprocess.py'
[Thu May 27 20:51:08.954546 2021] [mpm_prefork:notice] [pid 488869] AH00169: caught SIGTERM, shutting down
[Thu May 27 20:51:09.131319 2021] [mpm_prefork:notice] [pid 489019] AH00163: Apache/2.4.41 (Ubuntu) OpenSSL/1.1.1f mod_wsgi/4.6.8 Python/3.8 configured -- resuming normal operations
[Thu May 27 20:51:09.131408 2021] [core:notice] [pid 489019] AH00094: Command line: '/usr/sbin/apache2'
[Thu May 27 20:51:17.679142 2021] [wsgi:error] [pid 489024] [client 106.220.93.219:58737] mod_wsgi (pid=489024): Failed to exec Python script file '/var/www/gridsai/gridsai.wsgi'.
[Thu May 27 20:51:17.679236 2021] [wsgi:error] [pid 489024] [client 106.220.93.219:58737] mod_wsgi (pid=489024): Exception occurred processing WSGI script '/var/www/gridsai/gridsai.wsgi'.
[Thu May 27 20:51:17.681108 2021] [wsgi:error] [pid 489024] [client 106.220.93.219:58737] Traceback (most recent call last):
[Thu May 27 20:51:17.681173 2021] [wsgi:error] [pid 489024] [client 106.220.93.219:58737]   File "/var/www/gridsai/gridsai.wsgi", line 9, in <module>
[Thu May 27 20:51:17.681179 2021] [wsgi:error] [pid 489024] [client 106.220.93.219:58737]     from gridsai import app as application
[Thu May 27 20:51:17.681187 2021] [wsgi:error] [pid 489024] [client 106.220.93.219:58737]   File "/var/www/gridsai/gridsai/__init__.py", line 7, in <module>
[Thu May 27 20:51:17.681194 2021] [wsgi:error] [pid 489024] [client 106.220.93.219:58737]   File "<frozen importlib._bootstrap>", line 991, in _find_and_load
[Thu May 27 20:51:17.681203 2021] [wsgi:error] [pid 489024] [client 106.220.93.219:58737]   File "<frozen importlib._bootstrap>", line 975, in _find_and_load_unlocked
[Thu May 27 20:51:17.681213 2021] [wsgi:error] [pid 489024] [client 106.220.93.219:58737]   File "<frozen importlib._bootstrap>", line 671, in _load_unlocked
[Thu May 27 20:51:17.681220 2021] [wsgi:error] [pid 489024] [client 106.220.93.219:58737]   File "<frozen importlib._bootstrap_external>", line 779, in exec_module
[Thu May 27 20:51:17.681227 2021] [wsgi:error] [pid 489024] [client 106.220.93.219:58737]   File "<frozen importlib._bootstrap_external>", line 915, in get_code
[Thu May 27 20:51:17.681234 2021] [wsgi:error] [pid 489024] [client 106.220.93.219:58737]   File "<frozen importlib._bootstrap_external>", line 972, in get_data
[Thu May 27 20:51:17.681256 2021] [wsgi:error] [pid 489024] [client 106.220.93.219:58737] PermissionError: [Errno 13] Permission denied: '/var/www/gridsai/gridsai/shuffleprocess.py'
[Thu May 27 20:51:18.654399 2021] [wsgi:error] [pid 489021] [client 106.220.93.219:58738] mod_wsgi (pid=489021): Failed to exec Python script file '/var/www/gridsai/gridsai.wsgi'., referer: https://grids-ai.com/
[Thu May 27 20:51:18.654509 2021] [wsgi:error] [pid 489021] [client 106.220.93.219:58738] mod_wsgi (pid=489021): Exception occurred processing WSGI script '/var/www/gridsai/gridsai.wsgi'., referer: https://grids-ai.com/
[Thu May 27 20:51:18.657036 2021] [wsgi:error] [pid 489021] [client 106.220.93.219:58738] Traceback (most recent call last):, referer: https://grids-ai.com/
[Thu May 27 20:51:18.657121 2021] [wsgi:error] [pid 489021] [client 106.220.93.219:58738]   File "/var/www/gridsai/gridsai.wsgi", line 9, in <module>, referer: https://grids-ai.com/
[Thu May 27 20:51:18.657128 2021] [wsgi:error] [pid 489021] [client 106.220.93.219:58738]     from gridsai import app as application, referer: https://grids-ai.com/
[Thu May 27 20:51:18.657138 2021] [wsgi:error] [pid 489021] [client 106.220.93.219:58738]   File "/var/www/gridsai/gridsai/__init__.py", line 7, in <module>, referer: https://grids-ai.com/
[Thu May 27 20:51:18.657148 2021] [wsgi:error] [pid 489021] [client 106.220.93.219:58738]   File "<frozen importlib._bootstrap>", line 991, in _find_and_load, referer: https://grids-ai.com/
[Thu May 27 20:51:18.657158 2021] [wsgi:error] [pid 489021] [client 106.220.93.219:58738]   File "<frozen importlib._bootstrap>", line 975, in _find_and_load_unlocked, referer: https://grids-ai.com/
[Thu May 27 20:51:18.657169 2021] [wsgi:error] [pid 489021] [client 106.220.93.219:58738]   File "<frozen importlib._bootstrap>", line 671, in _load_unlocked, referer: https://grids-ai.com/
[Thu May 27 20:51:18.657179 2021] [wsgi:error] [pid 489021] [client 106.220.93.219:58738]   File "<frozen importlib._bootstrap_external>", line 779, in exec_module, referer: https://grids-ai.com/
[Thu May 27 20:51:18.657189 2021] [wsgi:error] [pid 489021] [client 106.220.93.219:58738]   File "<frozen importlib._bootstrap_external>", line 915, in get_code, referer: https://grids-ai.com/
[Thu May 27 20:51:18.657199 2021] [wsgi:error] [pid 489021] [client 106.220.93.219:58738]   File "<frozen importlib._bootstrap_external>", line 972, in get_data, referer: https://grids-ai.com/
[Thu May 27 20:51:18.657225 2021] [wsgi:error] [pid 489021] [client 106.220.93.219:58738] PermissionError: [Errno 13] Permission denied: '/var/www/gridsai/gridsai/shuffleprocess.py', referer: https://grids-ai.com/
